<mujoco>
  <compiler inertiafromgeom="true"/>
  <option gravity = "0 0 -9.81" integrator="implicitfast" timestep="0.001">
    <flag contact="enable" />
  </option >
  <!-- <include file="basic_scene.xml"/> -->
  <default>
    <joint limited="false"/>
  </default>
  <worldbody>
    <light diffuse=".5 .5 .5" pos="0 0 0.5" dir="0 0 -1"/>
    <geom type="plane" size="5 5 0.1" rgba="1 1 1 1"/>
    <body pos="0 0 .5" euler="0 -90 0">
      <joint name="pin" type="hinge" axis = "0 -1 0" pos="0 0 -0.5" armature="0" damping="1"/>
      <geom type="cylinder" size="0.05 0.5" rgba="0 .9 0 1" mass = "1"/>
        <!-- <geom type="sphere" size=".1" rgba=".9 .9 .1 1"/> -->
      <site name="endeff" type="sphere" size=".1" rgba=".9 .9 .1 1"/>
        <!-- <geom type="capsule" pos="0 0 0" size=".05 .1" euler="0 -90 0" rgba=".9 .9 .1 1"/> -->
        <!-- <site name="endeff" type="spehe" pos="0 0 0" size=".05 .1" euler="0 -90 0"  rgba=".9 .1 .9 1"/> -->
        <!-- <site type="ellipsoid" pos="0 .1 .3" size=".02 .03 .04" rgba=".9 .1 .9 1"/> -->
    </body>
  </worldbody>
  <actuator>
    <!-- <position name="pservo1" joint="pin" kp="1000" />
    <velocity name="vservo1" joint="pin" kv="100" /> -->
  </actuator>
  <!-- <contact>
    <exclude body1="hand" body2="left_finger"/>
    <exclude body1="hand" body2="right_finger"/>
  </contact> -->
  <actuator>
    <!-- <general name="torque" joint="pin" biasprm="0" gainprm="0" dynprm="0"  dyntype="user" biastype="user" gaintype="user"/> -->
    <motor name="torque" gear="1" joint="pin" />
  </actuator>
  <sensor>
    <force name="force" site ='endeff'/>
    <torque name="torque" site='endeff' />
    <!-- <framepos objtype="site" objname="tip"/>   -->
  </sensor>
</mujoco>